Workbook

Sheet Dataset
A1: No. | B1: feed_material | C1: perc_cellulose (%) | D1: perc_hemicellulose (%) | E1: perc_lignins (%) | F1: Size(mm) | G1: HBA | H1: HBD | I1: HBA:HBD | J1: S：L | K1: temp (°C) | L1: time (h) | M1: Lingin remove yield (%) | N1: Ref. | O1: Full Reference
A2: 1 | B2: wheat straw | C2: 34.8 | D2: 21.8 | E2: 19 | F2: 0.2 | G2: ChCl | H2: MEA | I2: 1:6 | J2: 1:20 | K2: 90 | L2: 12 | M2: 81 | N2: [1] | O2: =VLOOKUP(N2,Reference!A:B,2,) -> Zhao, Z.; Chen, X.; Ali, M. F.; Abdeltawab, A. A.; Yakout, S. M.; Yu, G. Pretreatment of wheat straw using basic ethanolamine-based deep eutectic solvents for improving enzymatic hydrolysis. Bioresource Technology 2018, 263, 325-333. DOI: https://doi.org/10.1016/j.biortech.2018.05.016.
A3: 2 | B3: wheat straw | C3: 34.8 | D3: 21.8 | E3: 19 | F3: 0.2 | G3: ChCl | H3: DEA | I3: 1:8 | J3: 1:20 | K3: 90 | L3: 12 | M3: 73.5 | N3: [1] | O3: =VLOOKUP(N3,Reference!A:B,2,) -> Zhao, Z.; Chen, X.; Ali, M. F.; Abdeltawab, A. A.; Yakout, S. M.; Yu, G. Pretreatment of wheat straw using basic ethanolamine-based deep eutectic solvents for improving enzymatic hydrolysis. Bioresource Technology 2018, 263, 325-333. DOI: https://doi.org/10.1016/j.biortech.2018.05.016.
A4: 3 | B4: wheat straw | C4: 34.8 | D4: 21.8 | E4: 19 | F4: 0.2 | G4: ChCl | H4: MDEA | I4: 1:10 | J4: 1:20 | K4: 90 | L4: 12 | M4: 44.6 | N4: [1] | O4: =VLOOKUP(N4,Reference!A:B,2,) -> Zhao, Z.; Chen, X.; Ali, M. F.; Abdeltawab, A. A.; Yakout, S. M.; Yu, G. Pretreatment of wheat straw using basic ethanolamine-based deep eutectic solvents for improving enzymatic hydrolysis. Bioresource Technology 2018, 263, 325-333. DOI: https://doi.org/10.1016/j.biortech.2018.05.016.
A5: 4 | B5: wheat straw | C5: 34.8 | D5: 21.8 | E5: 19 | F5: 0.2 | G5: ChCl | H5: AcAm | I5: 1:2 | J5: 1:20 | K5: 90 | L5: 12 | M5: 3.4 | N5: [1] | O5: =VLOOKUP(N5,Reference!A:B,2,) -> Zhao, Z.; Chen, X.; Ali, M. F.; Abdeltawab, A. A.; Yakout, S. M.; Yu, G. Pretreatment of wheat straw using basic ethanolamine-based deep eutectic solvents for improving enzymatic hydrolysis. Bioresource Technology 2018, 263, 325-333. DOI: https://doi.org/10.1016/j.biortech.2018.05.016.
A6: 5 | B6: wheat straw | C6: 34.8 | D6: 21.8 | E6: 19 | F6: 0.2 | G6: ChCl | H6: U | I6: 1:2 | J6: 1:20 | K6: 90 | L6: 12 | M6: 27.7 | N6: [1] | O6: =VLOOKUP(N6,Reference!A:B,2,) -> Zhao, Z.; Chen, X.; Ali, M. F.; Abdeltawab, A. A.; Yakout, S. M.; Yu, G. Pretreatment of wheat straw using basic ethanolamine-based deep eutectic solvents for improving enzymatic hydrolysis. Bioresource Technology 2018, 263, 325-333. DOI: https://doi.org/10.1016/j.biortech.2018.05.016.
A7: 6 | B7: wheat straw | C7: 34.8 | D7: 21.8 | E7: 19 | F7: 0.2 | G7: ChCl | H7: Gly | I7: 1:2 | J7: 1:20 | K7: 90 | L7: 12 | M7: 24.7 | N7: [1] | O7: =VLOOKUP(N7,Reference!A:B,2,) -> Zhao, Z.; Chen, X.; Ali, M. F.; Abdeltawab, A. A.; Yakout, S. M.; Yu, G. Pretreatment of wheat straw using basic ethanolamine-based deep eutectic solvents for improving enzymatic hydrolysis. Bioresource Technology 2018, 263, 325-333. DOI: https://doi.org/10.1016/j.biortech.2018.05.016.
A8: 7 | B8: wheat straw | C8: 34.8 | D8: 21.8 | E8: 19 | F8: 0.2 | G8: ChCl | H8: MEA | I8: 1:6 | J8: 1:20 | K8: 50 | L8: 12 | M8: 60.8 | N8: [1] | O8: =VLOOKUP(N8,Reference!A:B,2,) -> Zhao, Z.; Chen, X.; Ali, M. F.; Abdeltawab, A. A.; Yakout, S. M.; Yu, G. Pretreatment of wheat straw using basic ethanolamine-based deep eutectic solvents for improving enzymatic hydrolysis. Bioresource Technology 2018, 263, 325-333. DOI: https://doi.org/10.1016/j.biortech.2018.05.016.
A9: 8 | B9: wheat straw | C9: 34.8 | D9: 21.8 | E9: 19 | F9: 0.2 | G9: ChCl | H9: MEA | I9: 1:6 | J9: 1:20 | K9: 70 | L9: 12 | M9: 76.4 | N9: [1] | O9: =VLOOKUP(N9,Reference!A:B,2,) -> Zhao, Z.; Chen, X.; Ali, M. F.; Abdeltawab, A. A.; Yakout, S. M.; Yu, G. Pretreatment of wheat straw using basic ethanolamine-based deep eutectic solvents for improving enzymatic hydrolysis. Bioresource Technology 2018, 263, 325-333. DOI: https://doi.org/10.1016/j.biortech.2018.05.016.
A10: 9 | B10: wheat straw | C10: 34.8 | D10: 21.8 | E10: 19 | F10: 0.2 | G10: ChCl | H10: MEA | I10: 1:6 | J10: 1:20 | K10: 90 | L10: 12 | M10: 81 | N10: [1] | O10: =VLOOKUP(N10,Reference!A:B,2,) -> Zhao, Z.; Chen, X.; Ali, M. F.; Abdeltawab, A. A.; Yakout, S. M.; Yu, G. Pretreatment of wheat straw using basic ethanolamine-based deep eutectic solvents for improving enzymatic hydrolysis. Bioresource Technology 2018, 263, 325-333. DOI: https://doi.org/10.1016/j.biortech.2018.05.016.
A11: 10 | B11: wheat straw | C11: 34.8 | D11: 21.8 | E11: 19 | F11: 0.2 | G11: ChCl | H11: MEA | I11: 1:6 | J11: 1:20 | K11: 110 | L11: 12 | M11: 87.7 | N11: [1] | O11: =VLOOKUP(N11,Reference!A:B,2,) -> Zhao, Z.; Chen, X.; Ali, M. F.; Abdeltawab, A. A.; Yakout, S. M.; Yu, G. Pretreatment of wheat straw using basic ethanolamine-based deep eutectic solvents for improving enzymatic hydrolysis. Bioresource Technology 2018, 263, 325-333. DOI: https://doi.org/10.1016/j.biortech.2018.05.016.
A12: 11 | B12: wheat straw | C12: 34.8 | D12: 21.8 | E12: 19 | F12: 0.2 | G12: ChCl | H12: MEA | I12: 1:6 | J12: 1:20 | K12: 130 | L12: 12 | M12: 97.6 | N12: [1] | O12: =VLOOKUP(N12,Reference!A:B,2,) -> Zhao, Z.; Chen, X.; Ali, M. F.; Abdeltawab, A. A.; Yakout, S. M.; Yu, G. Pretreatment of wheat straw using basic ethanolamine-based deep eutectic solvents for improving enzymatic hydrolysis. Bioresource Technology 2018, 263, 325-333. DOI: https://doi.org/10.1016/j.biortech.2018.05.016.
A13: 12 | B13: wheat straw | C13: 34.8 | D13: 21.8 | E13: 19 | F13: 0.2 | G13: ChCl | H13: MEA | I13: 1:6 | J13: 1:20 | K13: 70 | L13: 1 | M13: 58.8 | N13: [1] | O13: =VLOOKUP(N13,Reference!A:B,2,) -> Zhao, Z.; Chen, X.; Ali, M. F.; Abdeltawab, A. A.; Yakout, S. M.; Yu, G. Pretreatment of wheat straw using basic ethanolamine-based deep eutectic solvents for improving enzymatic hydrolysis. Bioresource Technology 2018, 263, 325-333. DOI: https://doi.org/10.1016/j.biortech.2018.05.016.
... A23: 22 | B23: wheat straw | C23: 40.8 | D23: 29.2 | E23: 22.4 | F23: 0.38 | G23: ChCl | H23: LA | I23: 1:1 | J23: 1:10 | K23: 120 | L23: 9 | M23: 81.8 | N23: [3] | O23: =VLOOKUP(N23,Reference!A:B,2,) -> Lin, K.-T.; Wang, C.; Guo, M. F.; Aprà, E.; Ma, R.; Ragauskas, A. J.; Zhang, X. Lignin with controlled structural properties by N-heterocycle-based deep eutectic solvent extraction. Proceedings of the National Academy of Sciences 2023, 120 (32), e2307323120. DOI: 10.1073/pnas.2307323120(2023 ).
A24: 23 | B24: wheat straw | C24: 35.8 | D24: 20.4 | E24: 20.5 | F24: 0.83 | G24: ChCl | H24: p–TsOH | I24: 1.233 | J24: 1:19 | K24: 60 | L24: 0.1667 | M24: 42.9 | N24: [4] | O24: =VLOOKUP(N24,Reference!A:B,2,) -> Wang, W.; Gu, F.; Zhu, J. Y.; Sun, K.; Cai, Z.; Yao, S.; Wu, W.; Jin, Y. Fractionation of herbaceous biomass using a recyclable hydrotropic p–toluenesulfonic acid (p–TsOH)/choline chloride (ChCl) solvent system at low temperatures. Industrial Crops and Products 2020, 150, 112423. DOI: https://doi.org/10.1016/j.indcrop.2020.112423.
A25: 24 | B25: wheat straw | C25: 35.8 | D25: 20.4 | E25: 20.5 | F25: 0.83 | G25: ChCl | H25: p–TsOH | I25: 1.233 | J25: 1:19 | K25: 80 | L25: 0.3333 | M25: 58.6 | N25: [4] | O25: =VLOOKUP(N25,Reference!A:B,2,) -> Wang, W.; Gu, F.; Zhu, J. Y.; Sun, K.; Cai, Z.; Yao, S.; Wu, W.; Jin, Y. Fractionation of herbaceous biomass using a recyclable hydrotropic p–toluenesulfonic acid (p–TsOH)/choline chloride (ChCl) solvent system at low temperatures. Industrial Crops and Products 2020, 150, 112423. DOI: https://doi.org/10.1016/j.indcrop.2020.112423.
A26: 25 | B26: wheat straw | C26: 35.8 | D26: 20.4 | E26: 20.5 | F26: 0.83 | G26: ChCl | H26: p–TsOH | I26: 0.411 | J26: 1:19 | K26: 70 | L26: 0.1667 | M26: 68.6 | N26: [4] | O26: =VLOOKUP(N26,Reference!A:B,2,) -> Wang, W.; Gu, F.; Zhu, J. Y.; Sun, K.; Cai, Z.; Yao, S.; Wu, W.; Jin, Y. Fractionation of herbaceous biomass using a recyclable hydrotropic p–toluenesulfonic acid (p–TsOH)/choline chloride (ChCl) solvent system at low temperatures. Industrial Crops and Products 2020, 150, 112423. DOI: https://doi.org/10.1016/j.indcrop.2020.112423.
A27: 26 | B27: wheat straw | C27: 35.8 | D27: 20.4 | E27: 20.5 | F27: 0.83 | G27: ChCl | H27: p–TsOH | I27: 0.411 | J27: 1:19 | K27: 80 | L27: 0.3333 | M27: 88.9 | N27: [4] | O27: =VLOOKUP(N27,Reference!A:B,2,) -> Wang, W.; Gu, F.; Zhu, J. Y.; Sun, K.; Cai, Z.; Yao, S.; Wu, W.; Jin, Y. Fractionation of herbaceous biomass using a recyclable hydrotropic p–toluenesulfonic acid (p–TsOH)/choline chloride (ChCl) solvent system at low temperatures. Industrial Crops and Products 2020, 150, 112423. DOI: https://doi.org/10.1016/j.indcrop.2020.112423.
A28: 27 | B28: wheat straw | C28: 35.8 | D28: 20.4 | E28: 20.5 | F28: 0.83 | G28: ChCl | H28: p–TsOH | I28: 1.233 | J28: 1:19 | K28: 80 | L28: 2 | M28: 87.1 | N28: [4] | O28: =VLOOKUP(N28,Reference!A:B,2,) -> Wang, W.; Gu, F.; Zhu, J. Y.; Sun, K.; Cai, Z.; Yao, S.; Wu, W.; Jin, Y. Fractionation of herbaceous biomass using a recyclable hydrotropic p–toluenesulfonic acid (p–TsOH)/choline chloride (ChCl) solvent system at low temperatures. Industrial Crops and Products 2020, 150, 112423. DOI: https://doi.org/10.1016/j.indcrop.2020.112423.
A29: 28 | B29: wheat straw | C29: 35.8 | D29: 20.4 | E29: 20.5 | F29: 0.83 | G29: ChCl | H29: p–TsOH | I29: 0.411 | J29: 1:19 | K29: 80 | L29: 1 | M29: 87.1 | N29: [4] | O29: =VLOOKUP(N29,Reference!A:B,2,) -> Wang, W.; Gu, F.; Zhu, J. Y.; Sun, K.; Cai, Z.; Yao, S.; Wu, W.; Jin, Y. Fractionation of herbaceous biomass using a recyclable hydrotropic p–toluenesulfonic acid (p–TsOH)/choline chloride (ChCl) solvent system at low temperatures. Industrial Crops and Products 2020, 150, 112423. DOI: https://doi.org/10.1016/j.indcrop.2020.112423.
A30: 29 | B30: wheat straw | C30: 40.35 | D30: 30.52 | E30: 24.16 | F30: 0.38 | G30: ChCl | H30: EG | I30: 1:2 | J30: 1:20 | K30: 100 | L30: 12 | M30: 35.67 | N30: [5] | O30: =VLOOKUP(N30,Reference!A:B,2,) -> Tan, J.; Yu, D.; Yuan, J.; Wu, H.; Luo, H.; Zhang, H.; Li, X.; Li, H.; Yang, S. Efficient delignification of wheat straw for microbial lipid production enabled by a novel ternary deep eutectic solvent containing ethylene glycol. Fuel 2023, 347, 128485. DOI: https://doi.org/10.1016/j.fuel.2023.128485.
A31: 30 | B31: wheat straw | C31: 40.35 | D31: 30.52 | E31: 24.16 | F31: 0.38 | G31: ChCl | H31: CA | I31: 1:1 | J31: 1:20 | K31: 100 | L31: 12 | M31: 41.52 | N31: [5] | O31: =VLOOKUP(N31,Reference!A:B,2,) -> Tan, J.; Yu, D.; Yuan, J.; Wu, H.; Luo, H.; Zhang, H.; Li, X.; Li, H.; Yang, S. Efficient delignification of wheat straw for microbial lipid production enabled by a novel ternary deep eutectic solvent containing ethylene glycol. Fuel 2023, 347, 128485. DOI: https://doi.org/10.1016/j.fuel.2023.128485.
A32: 31 | B32: wheat straw | C32: 40.8 | D32: =74.7-C32 -> 33.9 | E32: 17.3 | F32: 0.023 | G32: ChCl | H32: U | I32: 1:2 | J32: 1:20 | K32: 80 | L32: 24 | M32: 6.277 | N32: [6] | O32: =VLOOKUP(N32,Reference!A:B,2,) -> Jablonsky; Skulcova; Kamenska; Vrska; Sima. Deep Eutectic Solvents: Fractionation of Wheat Straw. BIORESOURCES 2015, 2015,10(4) (-), 8039-8047.
A33: 32 | B33: wheat straw | C33: 40.8 | D33: 33.9 | E33: 17.3 | F33: 0.023 | G33: ChCl | H33: MNA | I33: 1:1 | J33: 1:20 | K33: 60 | L33: 24 | M33: 12.83 | N33: [6] | O33: =VLOOKUP(N33,Reference!A:B,2,) -> Jablonsky; Skulcova; Kamenska; Vrska; Sima. Deep Eutectic Solvents: Fractionation of Wheat Straw. BIORESOURCES 2015, 2015,10(4) (-), 8039-8047.
A34: 33 | B34: wheat straw | C34: 40.8 | D34: 33.9 | E34: 17.3 | F34: 0.023 | G34: ChCl | H34: LA | I34: 1:9 | J34: 1:20 | K34: 60 | L34: 24 | M34: 14.62 | N34: [6] | O34: =VLOOKUP(N34,Reference!A:B,2,) -> Jablonsky; Skulcova; Kamenska; Vrska; Sima. Deep Eutectic Solvents: Fractionation of Wheat Straw. BIORESOURCES 2015, 2015,10(4) (-), 8039-8047.
A35: 34 | B35: wheat straw | C35: 40.8 | D35: 33.9 | E35: 17.3 | F35: 0.023 | G35: ChCl | H35: MIA | I35: 1:1 | J35: 1:20 | K35: 80 | L35: 24 | M35: 21.62 | N35: [6] | O35: =VLOOKUP(N35,Reference!A:B,2,) -> Jablonsky; Skulcova; Kamenska; Vrska; Sima. Deep Eutectic Solvents: Fractionation of Wheat Straw. BIORESOURCES 2015, 2015,10(4) (-), 8039-8047.
A36: 35 | B36: wheat straw | C36: 40.8 | D36: 33.9 | E36: 17.3 | F36: 0.023 | G36: ChCl | H36: LA | I36: 1:10 | J36: 1:20 | K36: 60 | L36: 24 | M36: 29.13 | N36: [6] | O36: =VLOOKUP(N36,Reference!A:B,2,) -> Jablonsky; Skulcova; Kamenska; Vrska; Sima. Deep Eutectic Solvents: Fractionation of Wheat Straw. BIORESOURCES 2015, 2015,10(4) (-), 8039-8047.
A37: 36 | B37: wheat straw | C37: 40.8 | D37: 33.9 | E37: 17.3 | F37: 0.023 | G37: ChCl | H37: OAD | I37: 1:1 | J37: 1:20 | K37: 60 | L37: 24 | M37: 57.86 | N37: [6] | O37: =VLOOKUP(N37,Reference!A:B,2,) -> Jablonsky; Skulcova; Kamenska; Vrska; Sima. Deep Eutectic Solvents: Fractionation of Wheat Straw. BIORESOURCES 2015, 2015,10(4) (-), 8039-8047.
A38: 37 | B38: wheat straw | C38: 36.77 | D38: 24.98 | E38: 23.59 | F38: 0.25 | G38: ChCl | H38: LA | I38: 1:2 | J38: 1:20 | K38: 90 | L38: 6 | M38: 27.53 | N38: [7] | O38: =VLOOKUP(N38,Reference!A:B,2,) -> Ma, H.; Fu, P.; Zhao, J.; Lin, X.; Wu, W.; Yu, Z.; Xia, C.; Wang, Q.; Gao, M.; Zhou, J. Pretreatment of Wheat Straw Lignocelluloses by Deep Eutectic Solvent for Lignin Extraction. Molecules 2022, 27 (22), 7955.
A39: 38 | B39: wheat straw | C39: 36.77 | D39: 24.98 | E39: 23.59 | F39: 0.25 | G39: ChCl | H39: LA | I39: 1:2 | J39: 1:20 | K39: 90 | L39: 12 | M39: 50.42 | N39: [7] | O39: =VLOOKUP(N39,Reference!A:B,2,) -> Ma, H.; Fu, P.; Zhao, J.; Lin, X.; Wu, W.; Yu, Z.; Xia, C.; Wang, Q.; Gao, M.; Zhou, J. Pretreatment of Wheat Straw Lignocelluloses by Deep Eutectic Solvent for Lignin Extraction. Molecules 2022, 27 (22), 7955.
A40: 39 | B40: wheat straw | C40: 36.77 | D40: 24.98 | E40: 23.59 | F40: 0.25 | G40: ChCl | H40: LA | I40: 1:2 | J40: 1:20 | K40: 120 | L40: 6 | M40: 75.18 | N40: [7] | O40: =VLOOKUP(N40,Reference!A:B,2,) -> Ma, H.; Fu, P.; Zhao, J.; Lin, X.; Wu, W.; Yu, Z.; Xia, C.; Wang, Q.; Gao, M.; Zhou, J. Pretreatment of Wheat Straw Lignocelluloses by Deep Eutectic Solvent for Lignin Extraction. Molecules 2022, 27 (22), 7955.
A41: 40 | B41: wheat straw | C41: 36.77 | D41: 24.98 | E41: 23.59 | F41: 0.25 | G41: ChCl | H41: LA | I41: 1:2 | J41: 1:20 | K41: 120 | L41: 12 | M41: 88.16 | N41: [7] | O41: =VLOOKUP(N41,Reference!A:B,2,) -> Ma, H.; Fu, P.; Zhao, J.; Lin, X.; Wu, W.; Yu, Z.; Xia, C.; Wang, Q.; Gao, M.; Zhou, J. Pretreatment of Wheat Straw Lignocelluloses by Deep Eutectic Solvent for Lignin Extraction. Molecules 2022, 27 (22), 7955.
A42: 41 | B42: wheat straw | C42: 36.77 | D42: 24.98 | E42: 23.59 | F42: 0.25 | G42: ChCl | H42: LA | I42: 1:2 | J42: 1:20 | K42: 150 | L42: 6 | M42: 91.17 | N42: [7] | O42: =VLOOKUP(N42,Reference!A:B,2,) -> Ma, H.; Fu, P.; Zhao, J.; Lin, X.; Wu, W.; Yu, Z.; Xia, C.; Wang, Q.; Gao, M.; Zhou, J. Pretreatment of Wheat Straw Lignocelluloses by Deep Eutectic Solvent for Lignin Extraction. Molecules 2022, 27 (22), 7955.
A43: 42 | B43: wheat straw | C43: 36.77 | D43: 24.98 | E43: 23.59 | F43: 0.25 | G43: ChCl | H43: LA | I43: 1:2 | J43: 1:20 | K43: 150 | L43: 12 | M43: 86.61 | N43: [7] | O43: =VLOOKUP(N43,Reference!A:B,2,) -> Ma, H.; Fu, P.; Zhao, J.; Lin, X.; Wu, W.; Yu, Z.; Xia, C.; Wang, Q.; Gao, M.; Zhou, J. Pretreatment of Wheat Straw Lignocelluloses by Deep Eutectic Solvent for Lignin Extraction. Molecules 2022, 27 (22), 7955.
A44: 43 | B44: wheat straw | C44: 36.77 | D44: 24.98 | E44: 23.59 | F44: 0.25 | G44: ChCl | H44: LA | I44: 1:2 | J44: 1:20 | K44: 180 | L44: 6 | M44: 73.4 | N44: [7] | O44: =VLOOKUP(N44,Reference!A:B,2,) -> Ma, H.; Fu, P.; Zhao, J.; Lin, X.; Wu, W.; Yu, Z.; Xia, C.; Wang, Q.; Gao, M.; Zhou, J. Pretreatment of Wheat Straw Lignocelluloses by Deep Eutectic Solvent for Lignin Extraction. Molecules 2022, 27 (22), 7955.
... A103: 102 | B103: wheat straw | C103: 30.3 | D103: 16.7 | E103: 21.5 | F103: 1.2 | G103: ChCl | H103: Gly | I103: 1:2 | J103: 1:19 | K103: 150 | L103: 9 | M103: 30.5 | N103: [14] | O103: =VLOOKUP(N103,Reference!A:B,2,) -> Hossain, M. A.; Rahaman, M. S.; Yelle, D.; Shang, H.; Sun, Z.; Renneckar, S.; Dong, J.; Tulaphol, S.; Sathitsuksanoh, N. Effects of polyol-based deep eutectic solvents on the efficiency of rice straw enzymatic hydrolysis. Industrial Crops and Products 2021, 167, 113480. DOI: https://doi.org/10.1016/j.indcrop.2021.113480.
A104: 103 | B104: wheat straw | C104: 35.49 | D104: =16.03+2.51 -> 18.54 | E104: 14.84 | F104: 0.38 | G104: ChCl | H104: U | I104: 1:2 | J104: 1:20 | K104: 110 | L104: 4 | M104: 41.24 | N104: [15] | O104: =VLOOKUP(N104,Reference!A:B,2,) -> Pan, M.; Zhao, G.; Ding, C.; Wu, B.; Lian, Z.; Lian, H. Physicochemical transformation of rice straw after pretreatment with a deep eutectic solvent of choline chloride/urea. Carbohydrate Polymers 2017, 176, 307-314. DOI: https://doi.org/10.1016/j.carbpol.2017.08.088.
A105: 104 | B105: wheat straw | C105: 35.49 | D105: =16.03+2.51 -> 18.54 | E105: 14.84 | F105: 0.38 | G105: ChCl | H105: U | I105: 1:2 | J105: 1:20 | K105: 110 | L105: 6 | M105: 32.08 | N105: [15] | O105: =VLOOKUP(N105,Reference!A:B,2,) -> Pan, M.; Zhao, G.; Ding, C.; Wu, B.; Lian, Z.; Lian, H. Physicochemical transformation of rice straw after pretreatment with a deep eutectic solvent of choline chloride/urea. Carbohydrate Polymers 2017, 176, 307-314. DOI: https://doi.org/10.1016/j.carbpol.2017.08.088.
A106: 105 | B106: wheat straw | C106: 35.49 | D106: =16.03+2.51 -> 18.54 | E106: 14.84 | F106: 0.38 | G106: ChCl | H106: U | I106: 1:2 | J106: 1:20 | K106: 110 | L106: 8 | M106: 33.29 | N106: [15] | O106: =VLOOKUP(N106,Reference!A:B,2,) -> Pan, M.; Zhao, G.; Ding, C.; Wu, B.; Lian, Z.; Lian, H. Physicochemical transformation of rice straw after pretreatment with a deep eutectic solvent of choline chloride/urea. Carbohydrate Polymers 2017, 176, 307-314. DOI: https://doi.org/10.1016/j.carbpol.2017.08.088.
A107: 106 | B107: wheat straw | C107: 35.49 | D107: =16.03+2.51 -> 18.54 | E107: 14.84 | F107: 0.38 | G107: ChCl | H107: U | I107: 1:2 | J107: 1:20 | K107: 130 | L107: 4 | M107: 35.71 | N107: [15] | O107: =VLOOKUP(N107,Reference!A:B,2,) -> Pan, M.; Zhao, G.; Ding, C.; Wu, B.; Lian, Z.; Lian, H. Physicochemical transformation of rice straw after pretreatment with a deep eutectic solvent of choline chloride/urea. Carbohydrate Polymers 2017, 176, 307-314. DOI: https://doi.org/10.1016/j.carbpol.2017.08.088.
...

Sheet Reference
A1: List of references for experimental data.
A3: No | B3: Reference
A4: [1] | B4: Zhao, Z.; Chen, X.; Ali, M. F.; Abdeltawab, A. A.; Yakout, S. M.; Yu, G. Pretreatment of wheat straw using basic ethanolamine-based deep eutectic solvents for improving enzymatic hydrolysis. Bioresource Technology 2018, 263, 325-333. DOI: https://doi.org/10.1016/j.biortech.2018.05.016.
A5: [2] | B5: Lou, R.; Ma, R.; Lin, K.-t.; Ahamed, A.; Zhang, X. Facile Extraction of Wheat Straw by Deep Eutectic Solvent (DES) to Produce Lignin Nanoparticles. ACS Sustainable Chemistry & Engineering 2019, 7 (12), 10248-10256. DOI: 10.1021/acssuschemeng.8b05816.
A6: [3] | B6: Lin, K.-T.; Wang, C.; Guo, M. F.; Aprà, E.; Ma, R.; Ragauskas, A. J.; Zhang, X. Lignin with controlled structural properties by N-heterocycle-based deep eutectic solvent extraction. Proceedings of the National Academy of Sciences 2023, 120 (32), e2307323120. DOI: 10.1073/pnas.2307323120(2023 ).
A7: [4] | B7: Wang, W.; Gu, F.; Zhu, J. Y.; Sun, K.; Cai, Z.; Yao, S.; Wu, W.; Jin, Y. Fractionation of herbaceous biomass using a recyclable hydrotropic p–toluenesulfonic acid (p–TsOH)/choline chloride (ChCl) solvent system at low temperatures. Industrial Crops and Products 2020, 150, 112423. DOI: https://doi.org/10.1016/j.indcrop.2020.112423.
A8: [5] | B8: Tan, J.; Yu, D.; Yuan, J.; Wu, H.; Luo, H.; Zhang, H.; Li, X.; Li, H.; Yang, S. Efficient delignification of wheat straw for microbial lipid production enabled by a novel ternary deep eutectic solvent containing ethylene glycol. Fuel 2023, 347, 128485. DOI: https://doi.org/10.1016/j.fuel.2023.128485.
A9: [6] | B9: Jablonsky; Skulcova; Kamenska; Vrska; Sima. Deep Eutectic Solvents: Fractionation of Wheat Straw. BIORESOURCES 2015, 2015,10(4) (-), 8039-8047.
A10: [7] | B10: Ma, H.; Fu, P.; Zhao, J.; Lin, X.; Wu, W.; Yu, Z.; Xia, C.; Wang, Q.; Gao, M.; Zhou, J. Pretreatment of Wheat Straw Lignocelluloses by Deep Eutectic Solvent for Lignin Extraction. Molecules 2022, 27 (22), 7955.
A11: [8] | B11: Kumar, A. K.; Parikh, B. S.; Pravakar, M. Natural deep eutectic solvent mediated pretreatment of rice straw: bioanalytical characterization of lignin extract and enzymatic hydrolysis of pretreated biomass residue. Environmental Science and Pollution Research 2016, 23 (10), 9265-9275. DOI: 10.1007/s11356-015-4780-4.
A12: [9] | B12: Hou, X.-D.; Feng, G.-J.; Ye, M.; Huang, C.-M.; Zhang, Y. Significantly enhanced enzymatic hydrolysis of rice straw via a high-performance two-stage deep eutectic solvents synergistic pretreatment. Bioresource Technology 2017, 238, 139-146. DOI: https://doi.org/10.1016/j.biortech.2017.04.027.
A13: [10] | B13: Hou, X.-D.; Li, A.-L.; Lin, K.-P.; Wang, Y.-Y.; Kuang, Z.-Y.; Cao, S.-L. Insight into the structure-function relationships of deep eutectic solvents during rice straw pretreatment. Bioresource Technology 2018, 249, 261-267. DOI: https://doi.org/10.1016/j.biortech.2017.10.019.
A14: [11] | B14: Maibam, P. D.; Goyal, A. Approach to an efficient pretreatment method for rice straw by deep eutectic solvent for high saccharification efficiency. Bioresource Technology 2022, 351, 127057. DOI: https://doi.org/10.1016/j.biortech.2022.127057.
... A41: [38] | B41: Procentese, A.; Raganati, F.; Olivieri, G.; Russo, M. E.; Rehmann, L.; Marzocchella, A. Low-energy biomass pretreatment with deep eutectic solvents for bio-butanol production. Bioresource Technology 2017, 243, 464-473. DOI: https://doi.org/10.1016/j.biortech.2017.06.143.
